
Using pretrained model and tokenizer from allenai/unifiedqa-t5-3b on HuggingFace
Traceback (most recent call last):
  File "/scratch/general/vast/u1419542/miniconda3/envs/starcEnv/lib/python3.11/site-packages/pandas/core/indexes/base.py", line 3802, in get_loc
    return self._engine.get_loc(casted_key)
           ^^^^^^^^^^^^^^^^^^^^^^^^^^^^^^^^
  File "pandas/_libs/index.pyx", line 138, in pandas._libs.index.IndexEngine.get_loc
  File "pandas/_libs/index.pyx", line 165, in pandas._libs.index.IndexEngine.get_loc
  File "pandas/_libs/hashtable_class_helper.pxi", line 5745, in pandas._libs.hashtable.PyObjectHashTable.get_item
  File "pandas/_libs/hashtable_class_helper.pxi", line 5753, in pandas._libs.hashtable.PyObjectHashTable.get_item
KeyError: 0
The above exception was the direct cause of the following exception:
Traceback (most recent call last):
  File "/uufs/chpc.utah.edu/common/home/u1419542/ZARA/trainTest.py", line 475, in <module>
    main()
  File "/uufs/chpc.utah.edu/common/home/u1419542/ZARA/trainTest.py", line 382, in main
    trainData = trainDataByEpisode[episode].to_dict("records")
                ~~~~~~~~~~~~~~~~~~^^^^^^^^^
  File "/scratch/general/vast/u1419542/miniconda3/envs/starcEnv/lib/python3.11/site-packages/pandas/core/frame.py", line 3807, in __getitem__
    indexer = self.columns.get_loc(key)
              ^^^^^^^^^^^^^^^^^^^^^^^^^
  File "/scratch/general/vast/u1419542/miniconda3/envs/starcEnv/lib/python3.11/site-packages/pandas/core/indexes/base.py", line 3804, in get_loc
    raise KeyError(key) from err
KeyError: 0